ERROR 2025-08-31 15:04:58,730 log 9736 19640 Internal Server Error: /api/auth/token/
Traceback (most recent call last):
  File "C:\Users\Ghost\Desktop\Python_WEB\jwt_drf\venv\Lib\site-packages\django_redis\cache.py", line 29, in _decorator
    return method(self, *args, **kwargs)
  File "C:\Users\Ghost\Desktop\Python_WEB\jwt_drf\venv\Lib\site-packages\django_redis\cache.py", line 99, in _get
    return self.client.get(key, default=default, version=version, client=client)
           ~~~~~~~~~~~~~~~^^^^^^^^^^^^^^^^^^^^^^^^^^^^^^^^^^^^^^^^^^^^^^^^^^^^^^
  File "C:\Users\Ghost\Desktop\Python_WEB\jwt_drf\venv\Lib\site-packages\django_redis\client\default.py", line 300, in get
    raise ConnectionInterrupted(connection=client) from e
django_redis.exceptions.ConnectionInterrupted: Redis ConnectionError: Error 10061 connecting to 127.0.0.1:6379. No connection could be made because the target machine actively refused it.

During handling of the above exception, another exception occurred:

Traceback (most recent call last):
  File "C:\Users\Ghost\Desktop\Python_WEB\jwt_drf\venv\Lib\site-packages\django\core\handlers\exception.py", line 55, in inner
    response = get_response(request)
  File "C:\Users\Ghost\Desktop\Python_WEB\jwt_drf\venv\Lib\site-packages\django\core\handlers\base.py", line 197, in _get_response
    response = wrapped_callback(request, *callback_args, **callback_kwargs)
  File "C:\Users\Ghost\Desktop\Python_WEB\jwt_drf\venv\Lib\site-packages\django\views\decorators\csrf.py", line 65, in _view_wrapper
    return view_func(request, *args, **kwargs)
  File "C:\Users\Ghost\Desktop\Python_WEB\jwt_drf\venv\Lib\site-packages\django\views\generic\base.py", line 105, in view
    return self.dispatch(request, *args, **kwargs)
           ~~~~~~~~~~~~~^^^^^^^^^^^^^^^^^^^^^^^^^^
  File "C:\Users\Ghost\Desktop\Python_WEB\jwt_drf\venv\Lib\site-packages\rest_framework\views.py", line 515, in dispatch
    response = self.handle_exception(exc)
  File "C:\Users\Ghost\Desktop\Python_WEB\jwt_drf\venv\Lib\site-packages\rest_framework\views.py", line 475, in handle_exception
    self.raise_uncaught_exception(exc)
    ~~~~~~~~~~~~~~~~~~~~~~~~~~~~~^^^^^
  File "C:\Users\Ghost\Desktop\Python_WEB\jwt_drf\venv\Lib\site-packages\rest_framework\views.py", line 486, in raise_uncaught_exception
    raise exc
  File "C:\Users\Ghost\Desktop\Python_WEB\jwt_drf\venv\Lib\site-packages\rest_framework\views.py", line 503, in dispatch
    self.initial(request, *args, **kwargs)
    ~~~~~~~~~~~~^^^^^^^^^^^^^^^^^^^^^^^^^^
  File "C:\Users\Ghost\Desktop\Python_WEB\jwt_drf\venv\Lib\site-packages\rest_framework\views.py", line 422, in initial
    self.check_throttles(request)
    ~~~~~~~~~~~~~~~~~~~~^^^^^^^^^
  File "C:\Users\Ghost\Desktop\Python_WEB\jwt_drf\venv\Lib\site-packages\rest_framework\views.py", line 365, in check_throttles
    if not throttle.allow_request(request, self):
           ~~~~~~~~~~~~~~~~~~~~~~^^^^^^^^^^^^^^^
  File "C:\Users\Ghost\Desktop\Python_WEB\jwt_drf\venv\Lib\site-packages\rest_framework\throttling.py", line 123, in allow_request
    self.history = self.cache.get(self.key, [])
                   ~~~~~~~~~~~~~~^^^^^^^^^^^^^^
  File "C:\Users\Ghost\Desktop\Python_WEB\jwt_drf\venv\Lib\site-packages\django_redis\cache.py", line 92, in get
    value = self._get(key, default, version, client)
  File "C:\Users\Ghost\Desktop\Python_WEB\jwt_drf\venv\Lib\site-packages\django_redis\cache.py", line 36, in _decorator
    raise e.__cause__  # noqa: B904
    ^^^^^^^^^^^^^^^^^
  File "C:\Users\Ghost\Desktop\Python_WEB\jwt_drf\venv\Lib\site-packages\django_redis\client\default.py", line 298, in get
    value = client.get(key)
  File "C:\Users\Ghost\Desktop\Python_WEB\jwt_drf\venv\Lib\site-packages\redis\commands\core.py", line 1830, in get
    return self.execute_command("GET", name)
           ~~~~~~~~~~~~~~~~~~~~^^^^^^^^^^^^^
  File "C:\Users\Ghost\Desktop\Python_WEB\jwt_drf\venv\Lib\site-packages\redis\client.py", line 542, in execute_command
    conn = self.connection or pool.get_connection(command_name, **options)
                              ~~~~~~~~~~~~~~~~~~~^^^^^^^^^^^^^^^^^^^^^^^^^
  File "C:\Users\Ghost\Desktop\Python_WEB\jwt_drf\venv\Lib\site-packages\redis\connection.py", line 1109, in get_connection
    connection.connect()
    ~~~~~~~~~~~~~~~~~~^^
  File "C:\Users\Ghost\Desktop\Python_WEB\jwt_drf\venv\Lib\site-packages\redis\connection.py", line 282, in connect
    raise ConnectionError(self._error_message(e))
redis.exceptions.ConnectionError: Error 10061 connecting to 127.0.0.1:6379. No connection could be made because the target machine actively refused it.
ERROR 2025-08-31 15:04:58,759 basehttp 9736 19640 "POST /api/auth/token/ HTTP/1.1" 500 161764
ERROR 2025-08-31 15:05:48,029 log 22008 12604 Internal Server Error: /api/auth/token/
Traceback (most recent call last):
  File "C:\Users\Ghost\Desktop\Python_WEB\jwt_drf\venv\Lib\site-packages\django_redis\cache.py", line 29, in _decorator
    return method(self, *args, **kwargs)
  File "C:\Users\Ghost\Desktop\Python_WEB\jwt_drf\venv\Lib\site-packages\django_redis\cache.py", line 99, in _get
    return self.client.get(key, default=default, version=version, client=client)
           ~~~~~~~~~~~~~~~^^^^^^^^^^^^^^^^^^^^^^^^^^^^^^^^^^^^^^^^^^^^^^^^^^^^^^
  File "C:\Users\Ghost\Desktop\Python_WEB\jwt_drf\venv\Lib\site-packages\django_redis\client\default.py", line 300, in get
    raise ConnectionInterrupted(connection=client) from e
django_redis.exceptions.ConnectionInterrupted: Redis ConnectionError: Error 10061 connecting to 127.0.0.1:6379. No connection could be made because the target machine actively refused it.

During handling of the above exception, another exception occurred:

Traceback (most recent call last):
  File "C:\Users\Ghost\Desktop\Python_WEB\jwt_drf\venv\Lib\site-packages\django\core\handlers\exception.py", line 55, in inner
    response = get_response(request)
  File "C:\Users\Ghost\Desktop\Python_WEB\jwt_drf\venv\Lib\site-packages\django\core\handlers\base.py", line 197, in _get_response
    response = wrapped_callback(request, *callback_args, **callback_kwargs)
  File "C:\Users\Ghost\Desktop\Python_WEB\jwt_drf\venv\Lib\site-packages\django\views\decorators\csrf.py", line 65, in _view_wrapper
    return view_func(request, *args, **kwargs)
  File "C:\Users\Ghost\Desktop\Python_WEB\jwt_drf\venv\Lib\site-packages\django\views\generic\base.py", line 105, in view
    return self.dispatch(request, *args, **kwargs)
           ~~~~~~~~~~~~~^^^^^^^^^^^^^^^^^^^^^^^^^^
  File "C:\Users\Ghost\Desktop\Python_WEB\jwt_drf\venv\Lib\site-packages\rest_framework\views.py", line 515, in dispatch
    response = self.handle_exception(exc)
  File "C:\Users\Ghost\Desktop\Python_WEB\jwt_drf\venv\Lib\site-packages\rest_framework\views.py", line 475, in handle_exception
    self.raise_uncaught_exception(exc)
    ~~~~~~~~~~~~~~~~~~~~~~~~~~~~~^^^^^
  File "C:\Users\Ghost\Desktop\Python_WEB\jwt_drf\venv\Lib\site-packages\rest_framework\views.py", line 486, in raise_uncaught_exception
    raise exc
  File "C:\Users\Ghost\Desktop\Python_WEB\jwt_drf\venv\Lib\site-packages\rest_framework\views.py", line 503, in dispatch
    self.initial(request, *args, **kwargs)
    ~~~~~~~~~~~~^^^^^^^^^^^^^^^^^^^^^^^^^^
  File "C:\Users\Ghost\Desktop\Python_WEB\jwt_drf\venv\Lib\site-packages\rest_framework\views.py", line 422, in initial
    self.check_throttles(request)
    ~~~~~~~~~~~~~~~~~~~~^^^^^^^^^
  File "C:\Users\Ghost\Desktop\Python_WEB\jwt_drf\venv\Lib\site-packages\rest_framework\views.py", line 365, in check_throttles
    if not throttle.allow_request(request, self):
           ~~~~~~~~~~~~~~~~~~~~~~^^^^^^^^^^^^^^^
  File "C:\Users\Ghost\Desktop\Python_WEB\jwt_drf\venv\Lib\site-packages\rest_framework\throttling.py", line 123, in allow_request
    self.history = self.cache.get(self.key, [])
                   ~~~~~~~~~~~~~~^^^^^^^^^^^^^^
  File "C:\Users\Ghost\Desktop\Python_WEB\jwt_drf\venv\Lib\site-packages\django_redis\cache.py", line 92, in get
    value = self._get(key, default, version, client)
  File "C:\Users\Ghost\Desktop\Python_WEB\jwt_drf\venv\Lib\site-packages\django_redis\cache.py", line 36, in _decorator
    raise e.__cause__  # noqa: B904
    ^^^^^^^^^^^^^^^^^
  File "C:\Users\Ghost\Desktop\Python_WEB\jwt_drf\venv\Lib\site-packages\django_redis\client\default.py", line 298, in get
    value = client.get(key)
  File "C:\Users\Ghost\Desktop\Python_WEB\jwt_drf\venv\Lib\site-packages\redis\commands\core.py", line 1830, in get
    return self.execute_command("GET", name)
           ~~~~~~~~~~~~~~~~~~~~^^^^^^^^^^^^^
  File "C:\Users\Ghost\Desktop\Python_WEB\jwt_drf\venv\Lib\site-packages\redis\client.py", line 542, in execute_command
    conn = self.connection or pool.get_connection(command_name, **options)
                              ~~~~~~~~~~~~~~~~~~~^^^^^^^^^^^^^^^^^^^^^^^^^
  File "C:\Users\Ghost\Desktop\Python_WEB\jwt_drf\venv\Lib\site-packages\redis\connection.py", line 1109, in get_connection
    connection.connect()
    ~~~~~~~~~~~~~~~~~~^^
  File "C:\Users\Ghost\Desktop\Python_WEB\jwt_drf\venv\Lib\site-packages\redis\connection.py", line 282, in connect
    raise ConnectionError(self._error_message(e))
redis.exceptions.ConnectionError: Error 10061 connecting to 127.0.0.1:6379. No connection could be made because the target machine actively refused it.
ERROR 2025-08-31 15:05:48,048 basehttp 22008 12604 "GET /api/auth/token/ HTTP/1.1" 500 161750
ERROR 2025-08-31 15:09:30,100 log 22016 19940 Internal Server Error: /api/auth/token/
Traceback (most recent call last):
  File "C:\Users\Ghost\Desktop\Python_WEB\jwt_drf\venv\Lib\site-packages\django_redis\cache.py", line 29, in _decorator
    return method(self, *args, **kwargs)
  File "C:\Users\Ghost\Desktop\Python_WEB\jwt_drf\venv\Lib\site-packages\django_redis\cache.py", line 99, in _get
    return self.client.get(key, default=default, version=version, client=client)
           ~~~~~~~~~~~~~~~^^^^^^^^^^^^^^^^^^^^^^^^^^^^^^^^^^^^^^^^^^^^^^^^^^^^^^
  File "C:\Users\Ghost\Desktop\Python_WEB\jwt_drf\venv\Lib\site-packages\django_redis\client\default.py", line 300, in get
    raise ConnectionInterrupted(connection=client) from e
django_redis.exceptions.ConnectionInterrupted: Redis ConnectionError: Error 10061 connecting to 127.0.0.1:6379. No connection could be made because the target machine actively refused it.

During handling of the above exception, another exception occurred:

Traceback (most recent call last):
  File "C:\Users\Ghost\Desktop\Python_WEB\jwt_drf\venv\Lib\site-packages\django\core\handlers\exception.py", line 55, in inner
    response = get_response(request)
  File "C:\Users\Ghost\Desktop\Python_WEB\jwt_drf\venv\Lib\site-packages\django\core\handlers\base.py", line 197, in _get_response
    response = wrapped_callback(request, *callback_args, **callback_kwargs)
  File "C:\Users\Ghost\Desktop\Python_WEB\jwt_drf\venv\Lib\site-packages\django\views\decorators\csrf.py", line 65, in _view_wrapper
    return view_func(request, *args, **kwargs)
  File "C:\Users\Ghost\Desktop\Python_WEB\jwt_drf\venv\Lib\site-packages\django\views\generic\base.py", line 105, in view
    return self.dispatch(request, *args, **kwargs)
           ~~~~~~~~~~~~~^^^^^^^^^^^^^^^^^^^^^^^^^^
  File "C:\Users\Ghost\Desktop\Python_WEB\jwt_drf\venv\Lib\site-packages\rest_framework\views.py", line 515, in dispatch
    response = self.handle_exception(exc)
  File "C:\Users\Ghost\Desktop\Python_WEB\jwt_drf\venv\Lib\site-packages\rest_framework\views.py", line 475, in handle_exception
    self.raise_uncaught_exception(exc)
    ~~~~~~~~~~~~~~~~~~~~~~~~~~~~~^^^^^
  File "C:\Users\Ghost\Desktop\Python_WEB\jwt_drf\venv\Lib\site-packages\rest_framework\views.py", line 486, in raise_uncaught_exception
    raise exc
  File "C:\Users\Ghost\Desktop\Python_WEB\jwt_drf\venv\Lib\site-packages\rest_framework\views.py", line 503, in dispatch
    self.initial(request, *args, **kwargs)
    ~~~~~~~~~~~~^^^^^^^^^^^^^^^^^^^^^^^^^^
  File "C:\Users\Ghost\Desktop\Python_WEB\jwt_drf\venv\Lib\site-packages\rest_framework\views.py", line 422, in initial
    self.check_throttles(request)
    ~~~~~~~~~~~~~~~~~~~~^^^^^^^^^
  File "C:\Users\Ghost\Desktop\Python_WEB\jwt_drf\venv\Lib\site-packages\rest_framework\views.py", line 365, in check_throttles
    if not throttle.allow_request(request, self):
           ~~~~~~~~~~~~~~~~~~~~~~^^^^^^^^^^^^^^^
  File "C:\Users\Ghost\Desktop\Python_WEB\jwt_drf\venv\Lib\site-packages\rest_framework\throttling.py", line 123, in allow_request
    self.history = self.cache.get(self.key, [])
                   ~~~~~~~~~~~~~~^^^^^^^^^^^^^^
  File "C:\Users\Ghost\Desktop\Python_WEB\jwt_drf\venv\Lib\site-packages\django_redis\cache.py", line 92, in get
    value = self._get(key, default, version, client)
  File "C:\Users\Ghost\Desktop\Python_WEB\jwt_drf\venv\Lib\site-packages\django_redis\cache.py", line 36, in _decorator
    raise e.__cause__  # noqa: B904
    ^^^^^^^^^^^^^^^^^
  File "C:\Users\Ghost\Desktop\Python_WEB\jwt_drf\venv\Lib\site-packages\django_redis\client\default.py", line 298, in get
    value = client.get(key)
  File "C:\Users\Ghost\Desktop\Python_WEB\jwt_drf\venv\Lib\site-packages\redis\commands\core.py", line 1830, in get
    return self.execute_command("GET", name)
           ~~~~~~~~~~~~~~~~~~~~^^^^^^^^^^^^^
  File "C:\Users\Ghost\Desktop\Python_WEB\jwt_drf\venv\Lib\site-packages\redis\client.py", line 542, in execute_command
    conn = self.connection or pool.get_connection(command_name, **options)
                              ~~~~~~~~~~~~~~~~~~~^^^^^^^^^^^^^^^^^^^^^^^^^
  File "C:\Users\Ghost\Desktop\Python_WEB\jwt_drf\venv\Lib\site-packages\redis\connection.py", line 1109, in get_connection
    connection.connect()
    ~~~~~~~~~~~~~~~~~~^^
  File "C:\Users\Ghost\Desktop\Python_WEB\jwt_drf\venv\Lib\site-packages\redis\connection.py", line 282, in connect
    raise ConnectionError(self._error_message(e))
redis.exceptions.ConnectionError: Error 10061 connecting to 127.0.0.1:6379. No connection could be made because the target machine actively refused it.
ERROR 2025-08-31 15:09:30,110 basehttp 22016 19940 "GET /api/auth/token/ HTTP/1.1" 500 161750
ERROR 2025-08-31 15:12:55,403 log 23332 2924 Internal Server Error: /api/auth/token/
Traceback (most recent call last):
  File "C:\Users\Ghost\Desktop\Python_WEB\jwt_drf\venv\Lib\site-packages\django\db\backends\utils.py", line 105, in _execute
    return self.cursor.execute(sql, params)
           ~~~~~~~~~~~~~~~~~~~^^^^^^^^^^^^^
  File "C:\Users\Ghost\Desktop\Python_WEB\jwt_drf\venv\Lib\site-packages\django\db\backends\sqlite3\base.py", line 360, in execute
    return super().execute(query, params)
           ~~~~~~~~~~~~~~~^^^^^^^^^^^^^^^
sqlite3.OperationalError: no such column: Role_Based_auth_app_user.organization_id

The above exception was the direct cause of the following exception:

Traceback (most recent call last):
  File "C:\Users\Ghost\Desktop\Python_WEB\jwt_drf\venv\Lib\site-packages\django\core\handlers\exception.py", line 55, in inner
    response = get_response(request)
  File "C:\Users\Ghost\Desktop\Python_WEB\jwt_drf\venv\Lib\site-packages\django\core\handlers\base.py", line 197, in _get_response
    response = wrapped_callback(request, *callback_args, **callback_kwargs)
  File "C:\Users\Ghost\Desktop\Python_WEB\jwt_drf\venv\Lib\site-packages\django\views\decorators\csrf.py", line 65, in _view_wrapper
    return view_func(request, *args, **kwargs)
  File "C:\Users\Ghost\Desktop\Python_WEB\jwt_drf\venv\Lib\site-packages\django\views\generic\base.py", line 105, in view
    return self.dispatch(request, *args, **kwargs)
           ~~~~~~~~~~~~~^^^^^^^^^^^^^^^^^^^^^^^^^^
  File "C:\Users\Ghost\Desktop\Python_WEB\jwt_drf\venv\Lib\site-packages\rest_framework\views.py", line 515, in dispatch
    response = self.handle_exception(exc)
  File "C:\Users\Ghost\Desktop\Python_WEB\jwt_drf\venv\Lib\site-packages\rest_framework\views.py", line 475, in handle_exception
    self.raise_uncaught_exception(exc)
    ~~~~~~~~~~~~~~~~~~~~~~~~~~~~~^^^^^
  File "C:\Users\Ghost\Desktop\Python_WEB\jwt_drf\venv\Lib\site-packages\rest_framework\views.py", line 486, in raise_uncaught_exception
    raise exc
  File "C:\Users\Ghost\Desktop\Python_WEB\jwt_drf\venv\Lib\site-packages\rest_framework\views.py", line 512, in dispatch
    response = handler(request, *args, **kwargs)
  File "C:\Users\Ghost\Desktop\Python_WEB\jwt_drf\venv\Lib\site-packages\rest_framework_simplejwt\views.py", line 46, in post
    serializer.is_valid(raise_exception=True)
    ~~~~~~~~~~~~~~~~~~~^^^^^^^^^^^^^^^^^^^^^^
  File "C:\Users\Ghost\Desktop\Python_WEB\jwt_drf\venv\Lib\site-packages\rest_framework\serializers.py", line 225, in is_valid
    self._validated_data = self.run_validation(self.initial_data)
                           ~~~~~~~~~~~~~~~~~~~^^^^^^^^^^^^^^^^^^^
  File "C:\Users\Ghost\Desktop\Python_WEB\jwt_drf\venv\Lib\site-packages\rest_framework\serializers.py", line 447, in run_validation
    value = self.validate(value)
  File "C:\Users\Ghost\Desktop\Python_WEB\jwt_drf\venv\Lib\site-packages\rest_framework_simplejwt\serializers.py", line 73, in validate
    data = super().validate(attrs)
  File "C:\Users\Ghost\Desktop\Python_WEB\jwt_drf\venv\Lib\site-packages\rest_framework_simplejwt\serializers.py", line 54, in validate
    self.user = authenticate(**authenticate_kwargs)
                ~~~~~~~~~~~~^^^^^^^^^^^^^^^^^^^^^^^
  File "C:\Users\Ghost\Desktop\Python_WEB\jwt_drf\venv\Lib\site-packages\django\views\decorators\debug.py", line 75, in sensitive_variables_wrapper
    return func(*func_args, **func_kwargs)
  File "C:\Users\Ghost\Desktop\Python_WEB\jwt_drf\venv\Lib\site-packages\django\contrib\auth\__init__.py", line 114, in authenticate
    user = backend.authenticate(request, **credentials)
  File "C:\Users\Ghost\Desktop\Python_WEB\jwt_drf\venv\Lib\site-packages\django\contrib\auth\backends.py", line 65, in authenticate
    user = UserModel._default_manager.get_by_natural_key(username)
  File "C:\Users\Ghost\Desktop\Python_WEB\jwt_drf\venv\Lib\site-packages\django\contrib\auth\base_user.py", line 37, in get_by_natural_key
    return self.get(**{self.model.USERNAME_FIELD: username})
           ~~~~~~~~^^^^^^^^^^^^^^^^^^^^^^^^^^^^^^^^^^^^^^^^^
  File "C:\Users\Ghost\Desktop\Python_WEB\jwt_drf\venv\Lib\site-packages\django\db\models\manager.py", line 87, in manager_method
    return getattr(self.get_queryset(), name)(*args, **kwargs)
           ~~~~~~~~~~~~~~~~~~~~~~~~~~~~~~~~~~^^^^^^^^^^^^^^^^^
  File "C:\Users\Ghost\Desktop\Python_WEB\jwt_drf\venv\Lib\site-packages\django\db\models\query.py", line 629, in get
    num = len(clone)
  File "C:\Users\Ghost\Desktop\Python_WEB\jwt_drf\venv\Lib\site-packages\django\db\models\query.py", line 366, in __len__
    self._fetch_all()
    ~~~~~~~~~~~~~~~^^
  File "C:\Users\Ghost\Desktop\Python_WEB\jwt_drf\venv\Lib\site-packages\django\db\models\query.py", line 1949, in _fetch_all
    self._result_cache = list(self._iterable_class(self))
                         ~~~~^^^^^^^^^^^^^^^^^^^^^^^^^^^^
  File "C:\Users\Ghost\Desktop\Python_WEB\jwt_drf\venv\Lib\site-packages\django\db\models\query.py", line 91, in __iter__
    results = compiler.execute_sql(
        chunked_fetch=self.chunked_fetch, chunk_size=self.chunk_size
    )
  File "C:\Users\Ghost\Desktop\Python_WEB\jwt_drf\venv\Lib\site-packages\django\db\models\sql\compiler.py", line 1623, in execute_sql
    cursor.execute(sql, params)
    ~~~~~~~~~~~~~~^^^^^^^^^^^^^
  File "C:\Users\Ghost\Desktop\Python_WEB\jwt_drf\venv\Lib\site-packages\django\db\backends\utils.py", line 122, in execute
    return super().execute(sql, params)
           ~~~~~~~~~~~~~~~^^^^^^^^^^^^^
  File "C:\Users\Ghost\Desktop\Python_WEB\jwt_drf\venv\Lib\site-packages\django\db\backends\utils.py", line 79, in execute
    return self._execute_with_wrappers(
           ~~~~~~~~~~~~~~~~~~~~~~~~~~~^
        sql, params, many=False, executor=self._execute
        ^^^^^^^^^^^^^^^^^^^^^^^^^^^^^^^^^^^^^^^^^^^^^^^
    )
    ^
  File "C:\Users\Ghost\Desktop\Python_WEB\jwt_drf\venv\Lib\site-packages\django\db\backends\utils.py", line 92, in _execute_with_wrappers
    return executor(sql, params, many, context)
  File "C:\Users\Ghost\Desktop\Python_WEB\jwt_drf\venv\Lib\site-packages\django\db\backends\utils.py", line 100, in _execute
    with self.db.wrap_database_errors:
         ^^^^^^^^^^^^^^^^^^^^^^^^^^^^
  File "C:\Users\Ghost\Desktop\Python_WEB\jwt_drf\venv\Lib\site-packages\django\db\utils.py", line 91, in __exit__
    raise dj_exc_value.with_traceback(traceback) from exc_value
  File "C:\Users\Ghost\Desktop\Python_WEB\jwt_drf\venv\Lib\site-packages\django\db\backends\utils.py", line 105, in _execute
    return self.cursor.execute(sql, params)
           ~~~~~~~~~~~~~~~~~~~^^^^^^^^^^^^^
  File "C:\Users\Ghost\Desktop\Python_WEB\jwt_drf\venv\Lib\site-packages\django\db\backends\sqlite3\base.py", line 360, in execute
    return super().execute(query, params)
           ~~~~~~~~~~~~~~~^^^^^^^^^^^^^^^
django.db.utils.OperationalError: no such column: Role_Based_auth_app_user.organization_id
ERROR 2025-08-31 15:12:55,432 basehttp 23332 2924 "POST /api/auth/token/ HTTP/1.1" 500 232312
ERROR 2025-08-31 15:13:59,979 log 22772 8168 Internal Server Error: /api/auth/token/
Traceback (most recent call last):
  File "C:\Users\Ghost\Desktop\Python_WEB\jwt_drf\venv\Lib\site-packages\django\db\backends\utils.py", line 105, in _execute
    return self.cursor.execute(sql, params)
           ~~~~~~~~~~~~~~~~~~~^^^^^^^^^^^^^
  File "C:\Users\Ghost\Desktop\Python_WEB\jwt_drf\venv\Lib\site-packages\django\db\backends\sqlite3\base.py", line 360, in execute
    return super().execute(query, params)
           ~~~~~~~~~~~~~~~^^^^^^^^^^^^^^^
sqlite3.OperationalError: no such column: Role_Based_auth_app_user.organization_id

The above exception was the direct cause of the following exception:

Traceback (most recent call last):
  File "C:\Users\Ghost\Desktop\Python_WEB\jwt_drf\venv\Lib\site-packages\django\core\handlers\exception.py", line 55, in inner
    response = get_response(request)
  File "C:\Users\Ghost\Desktop\Python_WEB\jwt_drf\venv\Lib\site-packages\django\core\handlers\base.py", line 197, in _get_response
    response = wrapped_callback(request, *callback_args, **callback_kwargs)
  File "C:\Users\Ghost\Desktop\Python_WEB\jwt_drf\venv\Lib\site-packages\django\views\decorators\csrf.py", line 65, in _view_wrapper
    return view_func(request, *args, **kwargs)
  File "C:\Users\Ghost\Desktop\Python_WEB\jwt_drf\venv\Lib\site-packages\django\views\generic\base.py", line 105, in view
    return self.dispatch(request, *args, **kwargs)
           ~~~~~~~~~~~~~^^^^^^^^^^^^^^^^^^^^^^^^^^
  File "C:\Users\Ghost\Desktop\Python_WEB\jwt_drf\venv\Lib\site-packages\rest_framework\views.py", line 515, in dispatch
    response = self.handle_exception(exc)
  File "C:\Users\Ghost\Desktop\Python_WEB\jwt_drf\venv\Lib\site-packages\rest_framework\views.py", line 475, in handle_exception
    self.raise_uncaught_exception(exc)
    ~~~~~~~~~~~~~~~~~~~~~~~~~~~~~^^^^^
  File "C:\Users\Ghost\Desktop\Python_WEB\jwt_drf\venv\Lib\site-packages\rest_framework\views.py", line 486, in raise_uncaught_exception
    raise exc
  File "C:\Users\Ghost\Desktop\Python_WEB\jwt_drf\venv\Lib\site-packages\rest_framework\views.py", line 512, in dispatch
    response = handler(request, *args, **kwargs)
  File "C:\Users\Ghost\Desktop\Python_WEB\jwt_drf\venv\Lib\site-packages\rest_framework_simplejwt\views.py", line 46, in post
    serializer.is_valid(raise_exception=True)
    ~~~~~~~~~~~~~~~~~~~^^^^^^^^^^^^^^^^^^^^^^
  File "C:\Users\Ghost\Desktop\Python_WEB\jwt_drf\venv\Lib\site-packages\rest_framework\serializers.py", line 225, in is_valid
    self._validated_data = self.run_validation(self.initial_data)
                           ~~~~~~~~~~~~~~~~~~~^^^^^^^^^^^^^^^^^^^
  File "C:\Users\Ghost\Desktop\Python_WEB\jwt_drf\venv\Lib\site-packages\rest_framework\serializers.py", line 447, in run_validation
    value = self.validate(value)
  File "C:\Users\Ghost\Desktop\Python_WEB\jwt_drf\venv\Lib\site-packages\rest_framework_simplejwt\serializers.py", line 73, in validate
    data = super().validate(attrs)
  File "C:\Users\Ghost\Desktop\Python_WEB\jwt_drf\venv\Lib\site-packages\rest_framework_simplejwt\serializers.py", line 54, in validate
    self.user = authenticate(**authenticate_kwargs)
                ~~~~~~~~~~~~^^^^^^^^^^^^^^^^^^^^^^^
  File "C:\Users\Ghost\Desktop\Python_WEB\jwt_drf\venv\Lib\site-packages\django\views\decorators\debug.py", line 75, in sensitive_variables_wrapper
    return func(*func_args, **func_kwargs)
  File "C:\Users\Ghost\Desktop\Python_WEB\jwt_drf\venv\Lib\site-packages\django\contrib\auth\__init__.py", line 114, in authenticate
    user = backend.authenticate(request, **credentials)
  File "C:\Users\Ghost\Desktop\Python_WEB\jwt_drf\venv\Lib\site-packages\django\contrib\auth\backends.py", line 65, in authenticate
    user = UserModel._default_manager.get_by_natural_key(username)
  File "C:\Users\Ghost\Desktop\Python_WEB\jwt_drf\venv\Lib\site-packages\django\contrib\auth\base_user.py", line 37, in get_by_natural_key
    return self.get(**{self.model.USERNAME_FIELD: username})
           ~~~~~~~~^^^^^^^^^^^^^^^^^^^^^^^^^^^^^^^^^^^^^^^^^
  File "C:\Users\Ghost\Desktop\Python_WEB\jwt_drf\venv\Lib\site-packages\django\db\models\manager.py", line 87, in manager_method
    return getattr(self.get_queryset(), name)(*args, **kwargs)
           ~~~~~~~~~~~~~~~~~~~~~~~~~~~~~~~~~~^^^^^^^^^^^^^^^^^
  File "C:\Users\Ghost\Desktop\Python_WEB\jwt_drf\venv\Lib\site-packages\django\db\models\query.py", line 629, in get
    num = len(clone)
  File "C:\Users\Ghost\Desktop\Python_WEB\jwt_drf\venv\Lib\site-packages\django\db\models\query.py", line 366, in __len__
    self._fetch_all()
    ~~~~~~~~~~~~~~~^^
  File "C:\Users\Ghost\Desktop\Python_WEB\jwt_drf\venv\Lib\site-packages\django\db\models\query.py", line 1949, in _fetch_all
    self._result_cache = list(self._iterable_class(self))
                         ~~~~^^^^^^^^^^^^^^^^^^^^^^^^^^^^
  File "C:\Users\Ghost\Desktop\Python_WEB\jwt_drf\venv\Lib\site-packages\django\db\models\query.py", line 91, in __iter__
    results = compiler.execute_sql(
        chunked_fetch=self.chunked_fetch, chunk_size=self.chunk_size
    )
  File "C:\Users\Ghost\Desktop\Python_WEB\jwt_drf\venv\Lib\site-packages\django\db\models\sql\compiler.py", line 1623, in execute_sql
    cursor.execute(sql, params)
    ~~~~~~~~~~~~~~^^^^^^^^^^^^^
  File "C:\Users\Ghost\Desktop\Python_WEB\jwt_drf\venv\Lib\site-packages\django\db\backends\utils.py", line 122, in execute
    return super().execute(sql, params)
           ~~~~~~~~~~~~~~~^^^^^^^^^^^^^
  File "C:\Users\Ghost\Desktop\Python_WEB\jwt_drf\venv\Lib\site-packages\django\db\backends\utils.py", line 79, in execute
    return self._execute_with_wrappers(
           ~~~~~~~~~~~~~~~~~~~~~~~~~~~^
        sql, params, many=False, executor=self._execute
        ^^^^^^^^^^^^^^^^^^^^^^^^^^^^^^^^^^^^^^^^^^^^^^^
    )
    ^
  File "C:\Users\Ghost\Desktop\Python_WEB\jwt_drf\venv\Lib\site-packages\django\db\backends\utils.py", line 92, in _execute_with_wrappers
    return executor(sql, params, many, context)
  File "C:\Users\Ghost\Desktop\Python_WEB\jwt_drf\venv\Lib\site-packages\django\db\backends\utils.py", line 100, in _execute
    with self.db.wrap_database_errors:
         ^^^^^^^^^^^^^^^^^^^^^^^^^^^^
  File "C:\Users\Ghost\Desktop\Python_WEB\jwt_drf\venv\Lib\site-packages\django\db\utils.py", line 91, in __exit__
    raise dj_exc_value.with_traceback(traceback) from exc_value
  File "C:\Users\Ghost\Desktop\Python_WEB\jwt_drf\venv\Lib\site-packages\django\db\backends\utils.py", line 105, in _execute
    return self.cursor.execute(sql, params)
           ~~~~~~~~~~~~~~~~~~~^^^^^^^^^^^^^
  File "C:\Users\Ghost\Desktop\Python_WEB\jwt_drf\venv\Lib\site-packages\django\db\backends\sqlite3\base.py", line 360, in execute
    return super().execute(query, params)
           ~~~~~~~~~~~~~~~^^^^^^^^^^^^^^^
django.db.utils.OperationalError: no such column: Role_Based_auth_app_user.organization_id
ERROR 2025-08-31 15:13:59,989 basehttp 22772 8168 "POST /api/auth/token/ HTTP/1.1" 500 232312
